Workbook

Sheet SUMMARY
A1: CNC Router for Carbon Fiber Cutting — Cost Summary
A2: UMass Aeronautics · Rev 4, Aug 2026 · rescoped 400x400 · nothing ordered
A4: MACHINE
A5: 3-axis CNC router (GT2 belt on X/Y, lead screw on Z), 400 x 400 mm cutting area, 100 mm Z travel. 2040 V-slot dual-beam gantry (frame envelope 650x700mm PROVISIONAL, CAD to verify), box frame, no legs (floor/bench use). GT2 belts + V-wheels on X/Y, self-locking lead screw + TWO MGN12 rails / FOUR MGN12H blocks on Z. Makita RT0701CR spindle. GRBL on Arduino.
A6: Cuts nested ribs and brackets from carbon fiber sheet 1-5 mm, plus plywood, foam, acrylic. Accuracy target +/-0.5 mm. Dual gantry beams carry cutting torque in bending rather than twisting a single open-section extrusion. Electronics run positive-pressure filtered rather than sealed, since DRV8825s need airflow.
A8: WHAT CHANGED
A9: Cutting area 500x500 -> 400x400: smaller plates, shorter extrusion/belt runs, stiffer machine, lower cost.
A10: Z travel 127mm -> 100mm TARGET on a nominal 250mm rail: shorter standoff, less torsion. Travel is a target, not a proven result.
A11: Gantry beam: confirmed dual 2040 (not single) — required to keep tool-tip deflection inside the +/-0.5mm accuracy budget at 100mm Z standoff.
A12: PPE and spoilboard surfacing bit removed assumed to be already on hand.
A17: COST BY SUBSYSTEM
A18: Frame (extrusion, brackets, fasteners; plate stock pending Sean) | B18: =SUM(BOM!G6:G9) -> 130.98
A19: X/Y motion (wheels, spacers, belt, pulleys, idlers) | B19: =SUM(BOM!G11:G17) -> 80.94
A20: Z axis (lead screw, coupler, radial bearing, 2x MGN12 rail + 4 blocks) | B20: =SUM(BOM!G19:G23) -> 71.99
A21: Motors & electronics (steppers, driver kit, PSU, E-stop + contactor, printed enclosure, single drag chain + wire loom) | B21: =SUM(BOM!G25:G34) -> 185.5
A22: Spindle & tooling (Makita renewed, printed mount, collet reducer, end mills) | B22: =SUM(BOM!G36:G39) -> 139.99
A23: Workholding & dust (spoilboard, brush strip; vacuum/cyclone pending Sean) | B23: =SUM(BOM!G41:G43) -> 38
A24: Parts subtotal | B24: =BOM!G45 -> 647.4
A25: Shipping allowance (multi-vendor) | B25: =BOM!G46 -> 30
A26: Contingency 10% (folded into total, not hidden) | B26: =BOM!G47 -> 64.74
A28: TOTAL (all-in, includes contingency) | B28: =BOM!G48 -> 742.14
A29: Current costed items plus shipping, excluding contingency and unresolved items. | B29: =B24+B25 -> 677.4
A31: PENDING SEAN — not costed above, confirm before ordering
A32: Plate count corrected 3 -> 4 functional plates (added separate moving Z plate). Plate stock and dust extraction pending Sean.
A33: Shop vacuum + cyclone separator for CF dust extraction
A34: Mill session for the four-plate set — plate CAD must be verified before machining.
A35: Lead-screw axial retention / thrust support — unresolved, no collar, thrust bearing or BK/BF block selected; confirm design before ordering Z-axis hardware.
A36: MGN12 rail + block kit price — unverified against a live listing. Quantity confirmed at 2 kits (2 rails + 4 blocks); price is an estimate pending confirmation.
A38: Prices captured 7/18/2026 where verified; new/changed lines below are current estimates pending a live-listing check. Present total as planning price +/-10%.

Sheet BOM
A1: CNC Router BOM — UMass Aeronautics — Rev 4, four-plate architecture, FOR TEAM REVIEW
A2: GREEN = verified live listing (7/18). BLUE = estimate, confirm before ordering. STATUS tags: [FROZEN] architecture settled · [PROV] provisional, CAD must verify · [PENDING] unresolved, do not order.
A4: # | B4: Part | C4: Where to buy | D4: Alternative | E4: Price ($) | F4: Qty | G4: Line total ($) | H4: Price basis | I4: Notes | J4: Source
A5: FRAME
A6: 1 | B6: 2040 V-slot extrusion, generic (brackets/T-nuts bundled) | C6: amazon.com/dp/B0DY7GHY45 — Seekliny 4x1500mm 4-pack $95.99 | D6: OpenBuilds genuine via us.openbuilds.com if straightness QC fails twice | E6: 95.99 | F6: 1 pack (6m for 5.14m demand) | G6: =E6 -> 95.99 | H6: VERIFIED 7/18, qty recut | I6: One pack now covers full cut list with ~0.9m spare — down from 2 packs at 500x500 | J6: [PROV] Cut list from frame envelope 650x700mm, which is an ESTIMATE not a geometrically proven dimension. Cut list: 2x650 gantry beams, 2x700 Y rails, 2x610 cross members, 2x610 stringers = 5.14m. Re-cut list after CAD confirms frame envelope.
A7: 2 | B7: Corner brackets + gussets 20-series, M5 | C7: amazon.com/dp/B0F1B85397 — TOCLUX 20 sets w/ M5 T-nuts, $14.99 | D7: extrusion packs bundle more brackets | E7: 14.99 | F7: 1 kit | G7: =E7 -> 14.99 | H7: VERIFIED 7/18 | I7: Unaffected by scope change | J7: Carried from rev2
A8: 3 | B8: Fastener lot: M5 drop-in T-nuts, M5 bolt kit, M5 nylocks, M3 kit | C8: Amazon: 'M5 drop-in t nut 2020' + 'M5 socket head assortment' + 'M3 assortment' | D8: McMaster (pricier, faster) | E8: 20 | F8: 1 lot | G8: =E8 -> 20 | H8: est. (review) | I8: Real count comes off plate hole tables once plates are drawn from datasheets | J8: Pending plate CAD
A9: 4 | B9: Aluminum plate, 6mm — FOUR functional plates (see note) | C9: Pending Sean — makerspace stock | D9: McMaster/onlinemetals if stock falls through | E9: 0 | F9: 4 plates | G9: =E9 -> 0 | H9: PENDING SEAN + [PROV] envelopes | I9: FOUR functional plates, not three: (1) Left Y gantry plate ~180x240, (2) Right Y gantry plate ~180x240, (3) Fixed X carriage / Z backplate ~200x220, (4) Moving Z plate ~130-160 x 220-240. All envelopes [PROV], for stock planning only, NOT machining dimensions. STOCK: a single 305x610 blank is NOT a safe assumption for all four plates. Compare (A) one ~305x915 blank, or (B) one 305x610 blank plus a separate ~160x250 blank for the moving Z plate. Nesting efficiency not calculated — must account for edge margin, cutter diameter, clamping area, tabs/workholding, profile clearance, and internal features machined before external profiles. Mohamed must confirm available plate stock, usable workholding area, cutter clearance and the fourth-plate plan with Sean before ordering. | J9: Canonical architecture: four frozen functional plate roles
A10: X / Y MOTION
A11: 5 | B11: POM dual-V wheels w/ 625zz bearings, 13-pack | C11: amazon.com/dp/B08B4JDB67 — SIMAX3D 13pcs $9.99 | D11: OpenBuilds genuine (~$3.50 ea) if commodity wheels disappoint | E11: 19.98 | F11: 2 packs, 26 wheels (12 assumed + spares) | G11: =E11 -> 19.98 | H11: VERIFIED 7/18 price; qty [PROV] | I11: [PROV] 12 wheels ASSUMED (4 per Y gantry plate x2, 4 on X carriage). Final wheel count, arrangement, preload and eccentric placement must be verified in CAD against the dual-2040 gantry. CHECK BEFORE ORDERING: SIMAX3D listings disagree on bore, 5mm vs 6mm. 625zz standard bore is 5mm — measure the actual wheel with calipers before sizing the axle hole. | J11: [PROV] assumed 4/Y plate x2 + 4/X carriage = 12; CAD to verify
A12: 6 | B12: Eccentric spacers 6mm | C12: us.openbuilds.com 'Eccentric Spacer 6mm' | D12: Amazon '6mm eccentric spacer openbuilds' 10-pk | E12: 11 | F12: 6 | G12: =E12 -> 11 | H12: est. (review) | I12: One per wheel pair, half of 12 | J12: Topology: 6 of 12 wheel positions
A13: 7 | B13: Aluminum spacers 6mm (concentric) | C13: us.openbuilds.com 'Aluminum Spacer 6mm' | D13: Amazon assortment | E13: 5 | F13: 6 | G13: =E13 -> 5 | H13: est. (review) | I13: Other half of wheel pairs | J13: Topology: 6 of 12 wheel positions
A14: 8 | B14: GT2 open belt, 10mm wide, fiberglass core, 5m | C14: amazon.com/dp/B0F32PYF3W — $16.99 | D14: MOTOU 5m $19.99 | E14: 16.99 | F14: 5m spool (2.3m demand) | G14: =E14 -> 16.99 | H14: VERIFIED 7/18 | I14: 3 belt runs, ~720mm X + 2x770mm Y | J14: Belt topology diagram
A15: 9 | B15: GT2 pulleys 20T, 10mm belt, 5mm bore, 5-pack | C15: amazon.com/dp/B07BT6N12L — WINSINN $7.99 | D15: - | E15: 7.99 | F15: 3 (pack of 5) | G15: =E15 -> 7.99 | H15: VERIFIED 7/18, qty from topology | I15: One pulley per belt run, confirmed by diagram | J15: Belt topology: 1 per run x 3 runs
A16: 10 | B16: Smooth idlers, 10mm belt, M5 bore, 5-pack | C16: amazon.com/dp/B07BPHRSN5 — WINSINN, 2 packs $19.98 | D16: - | E16: 19.98 | F16: 6 (2 packs of 5) | G16: =E16 -> 19.98 | H16: VERIFIED 7/18, qty from topology | I16: Two idlers per belt run, confirmed by diagram — matches rev2's number, now traceable | J16: Belt topology: 2 per run x 3 runs
A17: 10b | B17: Belt clamps / anchor blocks | C17: 3D printed PETG (club filament) — or Amazon 'GT2 belt clamp 10mm' if printed creep | D17: Aluminium GT2 clamp blocks ~$9/10pk | E17: 0 | F17: 6 | G17: =E17 -> 0 | H17: printed, $0 | I17: Belt is clamped to the stationary rail at BOTH ends of every run. CAUTION: printed PETG clamps creep under sustained belt tension — budget periodic re-tensioning, or switch to metal if tension drifts. | J17: Belt topology: 2 clamps per run x 3 runs
A18: Z AXIS
A19: 11 | B19: T8x2 lead screw 300mm + anti-backlash nut, cut to 250mm | C19: amazon.com/dp/B07R38L317 — ReliaBot 300mm $8.99 | D19: check anti-backlash variant at checkout | E19: 8.99 | F19: 1 | G19: =E19 -> 8.99 | H19: VERIFIED 7/18 price; length [PROV] | I19: [PROV] 250mm is NOMINAL. Final cut length must be derived in CAD from block length, block spacing, usable 100mm travel, rail-end margins, nut length, coupler clearance and bottom-support clearance. Buy 300mm, cut to length. Do not cut inside the nut travel zone. | J19: [PROV] nominal; 100mm Z travel is a TARGET, not a proven result
A20: 12 | B20: Flexible coupler 5x8mm | C20: Amazon: '5mm 8mm flexible coupling' | D20: often bundled w/ screw — check first | E20: 7 | F20: 1 | G20: =E20 -> 7 | H20: est. (review) | I20: Unaffected by scope change | J20: Carried from rev2
A21: 13 | B21: 608-2RS bearing — screw bottom RADIAL support only | C21: printer spares / Amazon 10-pk | D21: - | E21: 2 | F21: 1 | G21: =E21 -> 2 | H21: est. (review) | I21: [FROZEN] Provides radial support only. It does NOT locate the screw axially. See the axial-retention line immediately below, which is unresolved. | J21: Canonical architecture: bottom bearing = radial support only
A22: 13b | B22: Lead-screw axial retention / thrust support — UNRESOLVED | C22: PENDING — do not order | D22: PENDING | E22: 0 | F22: PENDING | H22: [PENDING] no solution selected | I22: The 608 gives radial support only; nothing in this BOM currently locates the screw axially. Arrangement is UNRESOLVED — no collar, thrust bearing or BK/BF block has been selected, and none should be assumed. Also pending: exact Z motor-mount design, exact bottom-bearing bracket design, and whether those brackets are integral, separately machined, printed or purchased. Carries $0 because no part is chosen, NOT because it is free. | J22: Canonical architecture: axial retention explicitly pending
A23: 14 | B23: MGN12 rail + 2 blocks, 250mm nominal — TWO KITS (2 rails, 4 blocks total) | C23: Amazon: 'MGN12H 250mm 2 blocks' — order QTY 2 of this listing | D23: - | E23: 27 | F23: 2 kits = 2 rails + 4 blocks | G23: =E23*2 -> 54 | H23: [PROV] price unverified, qty corrected | I23: QTY CORRECTED: canonical Z architecture uses TWO parallel MGN12 rails fixed to the X carriage / Z backplate, and FOUR MGN12H blocks fixed to the moving Z plate. The prior line specified one rail and two blocks, which does not match the architecture and does not match what Sheet 2 already draws. The cited listing supplies 1 rail + 2 blocks per unit, so two units are required. PRICE PENDING: $27 was already an unverified estimate for one kit; two kits are shown at 2 x that estimate. Confirm against a live listing before ordering. [PROV] 250mm length is nominal — see lead-screw note. | J23: Canonical architecture: 2 rails fixed to backplate, 4 blocks on moving Z plate
A24: MOTORS & ELECTRONICS
A25: 15 | B25: NEMA 17, 45 Ncm, 1.5A — 5-pack | C25: stepperonline.com SKU 5-17HS15-1504S-X1 | D25: singles 17HS15-1504S1 @ $9.13 | E25: 39.77 | F25: 1 (4 + 1 spare) | G25: =E25 -> 39.77 | H25: VERIFIED 7/16 | I25: [FROZEN] 4 motors: 1 X (mounted ON the moving X carriage), 2 Y (one per moving Y gantry plate), 1 Z. Fifth motor is a spare. All four are the same non-geared part — there is no geared/non-geared distinction in this design. | J25: Canonical architecture: X on carriage, Y x2 on gantry plates, Z x1
A26: 16 | B26: CNC Shield V3 kit + DRV8825 5-pack | C26: amazon.com/dp/B07TT3C3HB $9.99 + amazon.com/dp/B0B3884KGS $9.99 | D26: A4988s from kit kept as spares | E26: 19.98 | F26: 1 | G26: =E26 -> 19.98 | H26: VERIFIED 7/18 | I26: Set driver current-limit to ~1.0-1.2A, not 1.5A — sealed-box airflow is limited even printed and vented | J26: Carried from rev2
A27: 17 | B27: EMI package: ground strap + ferrite chokes + shielded switch cable + fan | C27: Amazon: '24V 40mm fan' | D27: - | E27: 29 | F27: 1 | G27: =E27 -> 29 | H27: est. (review) | I27: Unaffected by scope change | J27: Carried from rev2
A28: 18 | B28: MeanWell LRS-350-24 PSU | C28: amazon.com/dp/B07SQLJG5L — $28.77 | D28: REJECTED: NVVV clone at $23.59 — same model number, not MeanWell | E28: 28.77 | F28: 1 | G28: =E28 -> 28.77 | H28: VERIFIED 7/18 | I28: Brand field must say MEAN WELL | J28: Carried from rev2
A29: 19 | B29: IEC inlet — REMOVED, salvage PC cord | C29: n/a | D29: n/a | E29: 0 | F29: 1 | G29: =E29 -> 0 | H29: cut for cost | I29: Third lever: use a salvaged PC power cord instead of buying new | J29: Team decision, this session
A30: 20 | B30: Limit switches (10-pk) + E-stop (2NC, 2-pk) + hookup wire | C30: amazon.com/dp/B07X142VGC $5.99 + amazon.com/dp/B07R8PTTDX $11.99 + wire ~$8 | D30: - | E30: 25.98 | F30: 1 lot | G30: =E30 -> 25.98 | H30: VERIFIED 7/18 | I30: 3 limit switches used (no dual-Y homing with A-axis cloned to Y; square gantry mechanically instead), rest spare | J30: Belt topology: 3 axes, no dual-Y homing
A31: 21 | B31: E-stop contactor — kills PSU and spindle mains together | C31: Amazon: 'DPST contactor 24V coil' or relay module rated for router load | D31: - | E31: 18 | F31: 1 | G31: =E31 -> 18 | H31: est. (review), NOT cut at any price | I31: Without this, E-stop halts GRBL motion but the Makita keeps spinning on wall power — this is the one safety gap that does not get value-engineered away | J31: Safety requirement, not a scope item
A32: 22 | B32: Electronics enclosure — 3D printed + gasket, positive-pressure filtered fan | C32: club filament + Amazon 'foam gasket seal' + small filtered fan | D32: IP65 box $18 if printed fails | E32: 6 | F32: 1 | G32: =E32 -> 6 | H32: cut for cost | I32: Printed positive-pressure box instead of sealed IP65 — cheaper and solves the DRV8825 airflow problem from the sealed-box design at the same time | J32: Third lever + airflow fix, this session
A33: 23 | B33: Drag chain x1 (frame->gantry) + wire loom for gantry->carriage run | C33: Amazon: 'drag chain 10x20 1m' + wire loom | D33: - | E33: 18 | F33: 1 chain + loom | G33: =E33 -> 18 | H33: cut for cost | I33: Second axis carries lighter cable load; loom is adequate short-term, add second chain later if wear becomes an issue | J33: Third lever, this session
A34: 24 | B34: Motor cable extensions — REMOVED, solder from stock wire | C34: n/a | D34: n/a | E34: 0 | F34: 1 | G34: =E34 -> 0 | H34: cut for cost | I34: Use hookup wire already in the fastener lot instead of buying pre-made extensions | J34: Third lever, this session
A35: SPINDLE & TOOLING
A36: 25 | B36: Makita RT0701CR — Amazon RENEWED | C36: amazon.com/dp/B01HG3Z6PC — $109.99 | D36: new RT0701C $159 if renewed unavailable | E36: 109.99 | F36: 1 | G36: =E36 -> 109.99 | H36: VERIFIED 7/18 | I36: Locked configuration: renewed only | J36: Carried from rev2
A37: 26 | B37: Spindle mount — 3D printed PETG | C37: club filament | D37: $12 Amazon 65mm aluminum mount | E37: 0 | F37: 1 | G37: =E37 -> 0 | H37: VERIFIED | I37: Retighten clamp bolts periodically | J37: Carried from rev2
A38: 27 | B38: Collet reducer 1/4 -> 1/8 in | C38: Amazon: '1/4 to 1/8 collet reducer router' | D38: Elaire precision (pricier) | E38: 8 | F38: 1 | G38: =E38 -> 8 | H38: est. (review) | I38: Burrs are 1/8 shank | J38: Carried from rev2
A39: 28 | B39: Carbide end mills for composites, 1/8 in | C39: Amazon: '1/8 carbide end mill fiberglass carbon fiber corn cob' — or eBay Drillman1 | D39: REJECTED: Rannb diamond-dust grinding burrs — engraving tool, cannot cut sheet | E39: 22 | F39: 1 pk | G39: =E39 -> 22 | H39: est. (review) | I39: Carbide with crosshatch flutes, not diamond-dust coating | J39: Carried from rev2
A40: WORKHOLDING & DUST
A41: 29 | B41: MDF 3/4in spoilboard + washer-head screws | C41: Home Depot local (project panel) | D41: club scrap if any | E41: 20 | F41: 1 | G41: =E41 -> 20 | H41: est. (review) | I41: Required — machine surfaces its own spoilboard | J41: Carried from rev2
...
